<?xml version="1.0" ?>
<sdf version="1.4">
  <model name="scara">
  
    <static>False</static>

    <!--Make the base of the Robot -->

    <link name="base">
        <pose>0 0 0 0 0 0 </pose>
        <collision name="collision_base">
          <pose>0 0 0.1 0 -0 0</pose>
          <geometry>
             <box>
                <size>0.2 0.2 0.1</size>
             </box>
          </geometry>
        </collision>
        <visual name="base_visual">
          <pose> 0 0 0.05 0 -0 0</pose>
          <geometry>
            <box>
               <size>0.2 0.2 0.1</size>
            </box>
          </geometry>
          <material>
            <ambient>0 0 0.4 1</ambient>
            <emissive>0 0 0.4 1</emissive>
          </material> 
        </visual>
     </link>
     <!-- Fix the base to the world -->
     <joint name="base_joint" type="fixed">
       <parent>world</parent>
       <child>base</child>
     </joint>
     <!-- Second link -->
     <link name="link_1">
       <pose>0 0 0.1 0 0 0</pose>
       <collision name="link1_collision">
         <pose>0 0 0.1 0 0 0</pose>
         <geometry>
            <cylinder>
                <length>0.4</length>
                <radius>0.05</radius>
            </cylinder>
         </geometry>
       </collision>
       <collision name="link1_fixed_collision">
          <geometry>
             <box>
                <size>0.4 0.1 0.05</size>
             </box>
          </geometry>
       </collision>

       <visual name="link1_visual">
         <pose>0 0 0.2 0 0 0</pose>
         <geometry>
            <cylinder>
               <length>0.4</length>
               <radius>0.05</radius>
            </cylinder>
         </geometry>
         <material>
            <ambient>0.5 0 0 1</ambient>
            <emissive>0.5 0 0 1</emissive>
         </material>
       </visual>
       <visual name="link1_fixed_visual">
         <pose>0.2 0 0.4 0 0 0</pose>
         <geometry>
            <box>
              <size>0.4 0.09 0.05</size>
            </box>
         </geometry>
         <material>
            <ambient>0 0.4 0 1</ambient>
            <emissive>0 0.3 0 1</emissive>
         </material>
       </visual>
     </link>
     <!--Fix the link_1 to base -->
     <joint name="joint_1" type="revolute">
         <child>link_1</child>
         <parent>base</parent>
         <axis>
           <xyz>0 0 1</xyz>
           <limit>
              <lower>-1e+16</lower>
              <upper>1e+16</upper>
           </limit>
           <dynamics>
             <damping>0.2</damping>
             <friction>0.1</friction>
             <spring_reference>0</spring_reference>
             <spring_stiffness>0</spring_stiffness>
           </dynamics>
         </axis>
     </joint>
     <!--Link_2 -->
     <link name="link_2">
        <pose>0.45 0 0.4 0 0 0</pose>
        <collision name="link2_collision">
          <pose>-0.03 0 0.15 0 0 0 </pose>
          <geometry>
            <cylinder>
               <length>0.2</length>
               <radius>0.05</radius>
            </cylinder>
          </geometry>
        </collision>

        <collision name="link2_fixed_collision_1">
          <pose>0.2 0 0.225 0 0 1.57</pose>
          <geometry>
             <box>
                <size>0.1 0.4 0.05</size>
             </box>
          </geometry>
        </collision>

        <collision name="link2_fixed_collision_2">
             <pose>0.43 0 0.23 0 0 0</pose>
             <geometry>
                 <sphere>
                     <radius>0.07</radius>
                 </sphere>
             </geometry>
        </collision>

        <visual name="link2_visual">
           <pose>-0.03 0 0.15 0 0 0 </pose>
           <geometry>
              <cylinder>
                 <length>0.15</length>
                 <radius>0.05</radius>
              </cylinder>
           </geometry>
           <material>
              <ambient>0.5 0 0 1</ambient>
              <emissive>0.5 0 0 1</emissive>
           </material>
        </visual>

        <visual name="link2_fixed_visual_1">
           <pose>0.15 0 0.200 0 0 1.57</pose>
           <geometry>
               <box>
                 <size>0.1 0.4 0.05</size>
               </box>
           </geometry>
           <material>
              <ambient>0 0.4 0 1</ambient>
              <emissive>0 0.3 0 1</emissive>
           </material>
        </visual>
        <visual name="link2_fixed_visual_2">
           <pose>0.38 0 0.21 0 0 0</pose>
           <geometry>
              <sphere>
                  <radius>0.05</radius>
              </sphere>
           </geometry>
           <material>
             <ambient>1 1 1 1</ambient>
             <emissive>1 1 1 1</emissive>
           </material>
        </visual>
      </link>
      <!-- Create joint 2 -->
      <joint name="joint_2" type="revolute">
         <parent>link_1</parent>
         <child>link_2</child>
         <axis>
            <xyz>0 0 1</xyz>
            <limit>
               <lower>-1e+16</lower>
               <upper>1e+16</upper>
            </limit>
            <dynamics>
               <damping>0.2</damping>
               <friction>0.1</friction>
               <spring_reference>0</spring_reference>
               <spring_stiffness>0</spring_stiffness>
            </dynamics>
            <use_parent_model_frame>1</use_parent_model_frame>
         </axis>
       </joint>
       <!-- Link 3 -->
       <link name="link_3">
          <pose>0.25 0 0.225 0 0 0</pose>

          <collision name="link3_collision">
            <pose>0.58 0 0.4 0 0 0</pose>
            <geometry>
                <cylinder>
                   <length>0.3</length>
                   <radius>0.03</radius> 
                </cylinder>
            </geometry>
         </collision>
       <visual name="link3_visual">
           <pose>0.58 0 0.4 0 0 0</pose>
           <geometry>
              <cylinder>
                 <length>0.4</length>
                 <radius>0.03</radius>
              </cylinder>
           </geometry>
           <material>
             <ambient>0 0 0 1</ambient>
             <emissive>0 0 0 1</emissive>
           </material>
         </visual>
         <velocity_decay/>       
      </link>
      <!-- Joint 3 -->
      <joint name="joint_3" type="prismatic">
         <child>link_3</child>
         <parent>link_2</parent>
         <axis>
           <xyz> 0 0.001593 -0.99999 </xyz>
           <limit>
              <lower>-0.2</lower>
              <upper>0.2</upper>
              <effort>1000</effort>
              <velocity>0.1</velocity>
           </limit>
           <dynamics>
              <damping>0.4</damping>
              <friction>50</friction>
              <spring_reference>0</spring_reference>
              <spring_stiffness>0</spring_stiffness>
           </dynamics>
        </axis>
      </joint>

      <link name="plate">
       <pose>0.828 -0.000 0.44 3.14 -0 0</pose>

        <collision name='collision_plate'>
         <pose>0 0 0.02 0 0 0</pose>
         <geometry>
            <cylinder>
               <length>0.02</length>
               <radius>0.03</radius>
            </cylinder>
         </geometry>
      </collision>

       <visual name="visual_plate">
        <pose>0 0 0.02 0 0 0</pose>
        <geometry>
           <cylinder>
              <length>0.02</length>
              <radius>0.05</radius>
           </cylinder>
        </geometry>
        <material>
           <script>
              <name>Gazebo/PurpleGlow</name>
              <uri>file://media/materials/scripts/gazebo.material</uri>
           </script>
        </material>
      </visual>
     </link>

     <joint name="joint_4" type="revolute">
        <parent>link_3</parent>
        <child>plate</child>
        <axis>
           <xyz>0 0 1</xyz>
           <limit>
              <lower>-1e+16</lower>
              <upper>1e+16</upper>
           </limit>
        <dynamics>
          <damping>0.4</damping>
          <friction>0.0001</friction>
          <spring_reference>0</spring_reference>
          <spring_stiffness>0</spring_stiffness>
        </dynamics>
      </axis>
     </joint>

      <link name="gripper">
      <pose>0 0 0.010 0 0 0</pose>
      <collision name="gripper_collision_1">
        <pose frame=''>0.86 0 0.39 0 -0 0</pose>
        <geometry>
           <box>
              <size>0.01 0.04 0.06</size>
           </box>
        </geometry>
      </collision>
       <collision name="gripper_collision_2">
        <pose frame=''>0.80 0 0.39 0 -0 0</pose>
        <geometry>
           <box>
              <size>0.01 0.04 0.06</size>
           </box>
        </geometry>
      </collision>

      <visual name="gripper_visual_1">
        <pose frame=''>0.86 0 0.39 0 -0 0</pose>
        <geometry>
           <box>
              <size>0.01 0.04 0.06</size>
           </box>
        </geometry>
       </visual>

       <visual name="gripper_visual_2">
        <pose frame=''>0.80 0 0.39 0 -0 0</pose>
        <geometry>
           <box>
              <size>0.01 0.04 0.06</size>
           </box>
        </geometry>
       </visual>
     </link>

     <joint name="joint_5" type="fixed">
        <parent>plate</parent>
        <child>gripper</child>
     </joint>

 </model>
</sdf>

